
# Created by Ruins mod version 17.1 Ingame Parser
# authoring Player: pikminman13

# criterion expression specifying mod ids required to load template
# may include plus (AND), minus (AND NOT), comma (OR), and parentheses
# all required mods listed must be present; no prohibited mods can be
requiredMods=
# likelihood this template will be chosen relative to all others
# e.g., a weight=6 template is chosen 3X as often as one with weight=2
weight=1
# list of other biomes in which this template may spawn
# biome corresponding to directory is always assumed, listed or not
# generic templates should leave this list empty
biomesToSpawnIn=Moon
# criterion expression specifying types of biome where template spawns
# this is in addition to those explicitly listed as biomesToSpawnIn
# generic templates should leave this list empty
biomeTypesToSpawnIn=
# list of biomes in which this template may not spawn
# takes precedence over biomeTypesToSpawnIn, but NOT biomesToSpawnIn
# should be empty if biomeTypesToSpawnIn is empty
biomesToNotSpawnIn=
# depth template is pushed down into the surface when built
# offset is min/max range of random additional bury depth
embed_into_distance=0
random_height_offset=0,0
# whitelist/blacklist of block types on which template may be built
# specify one, not both; leave the other empty (both empty = allow all)
acceptable_target_blocks=
unacceptable_target_blocks=flowing_water,water,flowing_lava,lava,grass,sand,gravel,stone,copper_ore
# size of template (#layers, #rows per layer, #blocks per row)
dimensions=10,15,15
# max number of missing blocks allowed in surface beneath template
allowable_overhang=0
# depth/height limit affected by terrain leveling
# also maximum bumpiness tolerated in surface beneath template
max_leveling=2
# padding applied to all sides of template horizontal footprint
# expands area affected by terrain leveling (-1 = no leveling)
leveling_buffer=0
# do not rotate template randomly when built (1 = no rotation)
preventRotation=0
# treat water/lava blocks as air and protect them from rule0 (1 = yes)
preserve_water=0
preserve_lava=0
# minimum distance this template must have from instances of itself
uniqueMinDistance=0
# min/max distances this template can be from world spawn (0 = no limit)
# only applies to overworld--i.e., dimension 0
spawnMinDistance=0
spawnMaxDistance=0
# other template built nearby whenever this one is
# syntax: <name>;<relativeX>;<maxYdifference>;<relativeZ>[;<chance>]
# may be used more than once to specify multiple neighbors
adjoining_template=

rule1=0,100,galacticraftcore:basic_block_moon-5
rule2=0,100,chisel:iron-4
rule3=0,100,minecraft:bedrock-0
rule4=0,100,chisel:futura-0
rule5=0,100,minecraft:beacon-0
rule6=0,100,minecraft:glowstone-0
rule7=0,100,environmentaltech:aethium_stairs-1
rule8=0,100,minecraft:stained_glass-10
rule9=0,100,minecraft:stained_glass-11
rule10=0,100,minecraft:stained_glass-1
rule11=0,100,minecraft:stained_glass-5
rule12=0,100,minecraft:stained_glass-4
rule13=0,100,minecraft:stained_glass-14
rule14=0,100,minecraft:stained_glass-3
rule15=0,100,chisel:factory-12
rule16=0,100,chisel:antiblock-5
rule17=0,100,chisel:antiblock-4
rule18=0,100,chisel:antiblock-14
rule19=0,100,chisel:antiblock-10
rule20=0,100,chisel:laboratory-15
rule21=0,100,chisel:antiblock-11
rule22=0,100,chisel:antiblock-1
rule23=0,100,chisel:antiblock-12
rule24=0,100,chisel:glassdyedpurple-0
rule25=0,100,chisel:glassdyedblue-0
rule26=0,100,chisel:glassdyedorange-0
rule27=0,100,chisel:glassdyedlime-0
rule28=0,100,chisel:glassdyedyellow-0
rule29=0,100,modularmachinery:blockoutputbus-0
rule30=0,100,modularmachinery:blockcontroller-3
rule31=0,100,modularmachinery:blockenergyinputhatch-7
rule32=0,100,chisel:glassdyedred-0
rule33=0,100,chisel:glassdyedlightblue-0

layer
0,0,0,0,0,0,1,1,1,0,0,0,0,0,0
0,0,0,0,1,1,2,2,2,1,1,0,0,0,0
0,0,0,1,2,2,2,2,2,2,2,1,0,0,0
0,0,1,2,2,2,2,2,2,2,2,2,1,0,0
0,1,2,2,2,2,2,2,2,2,2,2,2,1,0
0,1,2,2,2,2,2,2,2,2,2,2,2,1,0
1,2,2,2,2,2,2,2,2,2,2,2,2,2,1
1,2,2,2,2,2,2,2,2,2,2,2,2,2,1
1,2,2,2,2,2,2,2,2,2,2,2,2,2,1
0,1,2,2,2,2,2,2,2,2,2,2,2,1,0
0,1,2,2,2,2,2,2,2,2,2,2,2,1,0
0,0,1,2,2,2,2,2,2,2,2,2,1,0,0
0,0,0,1,2,2,2,2,2,2,2,1,0,0,0
0,0,0,0,1,1,2,2,2,1,1,0,0,0,0
0,0,0,0,0,0,1,1,1,0,0,0,0,0,0
endlayer

layer
0,0,0,0,0,0,0,0,0,0,0,0,0,0,0
0,0,0,0,0,0,0,2,0,0,0,0,0,0,0
0,0,0,0,2,2,2,3,2,2,2,0,0,0,0
0,0,0,2,3,4,3,5,3,4,3,2,0,0,0
0,0,2,3,5,3,0,3,0,3,5,3,2,0,0
0,0,2,4,3,0,0,6,0,0,3,4,2,0,0
0,0,2,3,0,0,3,3,3,0,0,3,2,0,0
0,2,3,5,3,6,3,3,3,6,3,5,3,2,0
0,0,2,3,0,0,3,3,3,0,0,3,2,0,0
0,0,2,4,3,0,0,6,0,0,3,4,2,0,0
0,0,2,3,5,3,0,0,0,3,5,3,2,0,0
0,0,0,2,3,4,0,0,0,4,3,2,0,0,0
0,0,0,0,2,2,2,2,2,2,2,0,0,0,0
0,0,0,0,0,0,2,2,2,0,0,0,0,0,0
0,0,0,0,0,0,7,7,7,0,0,0,0,0,0
endlayer

layer
0,0,0,0,0,0,0,0,0,0,0,0,0,0,0
0,0,0,0,0,0,0,2,0,0,0,0,0,0,0
0,0,0,0,2,2,2,3,2,2,2,0,0,0,0
0,0,0,2,3,4,3,8,3,4,3,2,0,0,0
0,0,2,3,10,3,0,3,0,3,9,3,2,0,0
0,0,2,4,3,0,0,0,0,0,3,4,2,0,0
0,0,2,3,0,0,0,3,0,0,0,3,2,0,0
0,2,3,12,3,0,3,3,3,0,3,11,3,2,0
0,0,2,3,0,0,0,3,0,0,0,3,2,0,0
0,0,2,4,3,0,0,0,0,0,3,4,2,0,0
0,0,2,3,14,3,0,0,0,3,13,3,2,0,0
0,0,0,2,3,4,0,0,0,4,3,2,0,0,0
0,0,0,0,2,2,2,2,2,2,2,0,0,0,0
0,0,0,0,0,0,7,7,7,0,0,0,0,0,0
0,0,0,0,0,0,0,0,0,0,0,0,0,0,0
endlayer

layer
0,0,0,0,0,0,0,0,0,0,0,0,0,0,0
0,0,0,0,0,0,0,0,0,0,0,0,0,0,0
0,0,0,0,0,0,2,2,2,0,0,0,0,0,0
0,0,0,0,2,4,15,3,15,4,2,0,0,0,0
0,0,0,2,3,15,15,15,15,15,3,2,0,0,0
0,0,0,4,15,15,15,15,15,15,15,4,0,0,0
0,0,2,15,15,15,15,15,15,15,15,15,2,0,0
0,0,2,3,15,15,15,15,15,15,15,3,2,0,0
0,0,2,15,15,15,15,15,15,15,15,15,2,0,0
0,0,0,4,15,15,15,15,15,15,15,4,0,0,0
0,0,0,2,3,15,15,15,15,15,3,2,0,0,0
0,0,0,0,2,4,15,15,15,4,2,0,0,0,0
0,0,0,0,0,0,7,7,7,0,0,0,0,0,0
0,0,0,0,0,0,0,0,0,0,0,0,0,0,0
0,0,0,0,0,0,0,0,0,0,0,0,0,0,0
endlayer

layer
0,0,0,0,0,0,0,0,0,0,0,0,0,0,0
0,0,0,0,0,0,0,0,0,0,0,0,0,0,0
0,0,0,0,0,0,2,2,2,0,0,0,0,0,0
0,0,0,0,2,4,0,16,0,4,2,0,0,0,0
0,0,0,2,18,0,0,0,0,0,17,2,0,0,0
0,0,0,4,0,0,0,0,0,0,0,4,0,0,0
0,0,2,0,0,0,0,0,0,0,0,0,2,0,0
0,0,2,21,0,0,20,20,20,0,0,19,2,0,0
0,0,2,0,0,0,0,0,0,0,0,0,2,0,0
0,0,0,4,0,0,0,0,0,0,0,4,0,0,0
0,0,0,2,23,0,0,0,0,0,22,2,0,0,0
0,0,0,0,2,4,0,0,0,4,2,0,0,0,0
0,0,0,0,0,0,0,0,0,0,0,0,0,0,0
0,0,0,0,0,0,0,0,0,0,0,0,0,0,0
0,0,0,0,0,0,0,0,0,0,0,0,0,0,0
endlayer

layer
0,0,0,0,0,0,0,0,0,0,0,0,0,0,0
0,0,0,0,0,0,0,0,0,0,0,0,0,0,0
0,0,0,0,0,0,24,24,24,0,0,0,0,0,0
0,0,0,0,26,4,0,0,0,4,25,0,0,0,0
0,0,0,26,0,0,0,0,0,0,0,25,0,0,0
0,0,0,4,0,0,0,0,0,0,0,4,0,0,0
0,0,28,0,0,0,0,0,0,0,0,0,27,0,0
0,0,28,0,0,0,31,30,29,0,0,0,27,0,0
0,0,28,0,0,0,0,0,0,0,0,0,27,0,0
0,0,0,4,0,0,0,0,0,0,0,4,0,0,0
0,0,0,33,0,0,0,0,0,0,0,32,0,0,0
0,0,0,0,33,4,0,0,0,4,32,0,0,0,0
0,0,0,0,0,0,0,0,0,0,0,0,0,0,0
0,0,0,0,0,0,0,0,0,0,0,0,0,0,0
0,0,0,0,0,0,0,0,0,0,0,0,0,0,0
endlayer

layer
0,0,0,0,0,0,0,0,0,0,0,0,0,0,0
0,0,0,0,0,0,0,0,0,0,0,0,0,0,0
0,0,0,0,0,0,2,2,2,0,0,0,0,0,0
0,0,0,0,2,4,0,0,0,4,2,0,0,0,0
0,0,0,2,0,0,0,0,0,0,0,2,0,0,0
0,0,0,4,0,0,0,0,0,0,0,4,0,0,0
0,0,2,0,0,0,0,0,0,0,0,0,2,0,0
0,0,2,0,0,0,0,0,0,0,0,0,2,0,0
0,0,2,0,0,0,0,0,0,0,0,0,2,0,0
0,0,0,4,0,0,0,0,0,0,0,4,0,0,0
0,0,0,2,0,0,0,0,0,0,0,2,0,0,0
0,0,0,0,2,4,0,0,0,4,2,0,0,0,0
0,0,0,0,0,0,0,0,0,0,0,0,0,0,0
0,0,0,0,0,0,0,0,0,0,0,0,0,0,0
0,0,0,0,0,0,0,0,0,0,0,0,0,0,0
endlayer

layer
0,0,0,0,0,0,0,0,0,0,0,0,0,0,0
0,0,0,0,0,0,0,0,0,0,0,0,0,0,0
0,0,0,0,0,0,0,0,0,0,0,0,0,0,0
0,0,0,0,0,4,0,0,0,4,0,0,0,0,0
0,0,0,0,0,0,0,0,0,0,0,0,0,0,0
0,0,0,4,0,0,0,0,0,0,0,4,0,0,0
0,0,0,0,0,0,0,0,0,0,0,0,0,0,0
0,0,0,0,0,0,0,0,0,0,0,0,0,0,0
0,0,0,0,0,0,0,0,0,0,0,0,0,0,0
0,0,0,4,0,0,0,0,0,0,0,4,0,0,0
0,0,0,0,0,0,0,0,0,0,0,0,0,0,0
0,0,0,0,0,4,0,0,0,4,0,0,0,0,0
0,0,0,0,0,0,0,0,0,0,0,0,0,0,0
0,0,0,0,0,0,0,0,0,0,0,0,0,0,0
0,0,0,0,0,0,0,0,0,0,0,0,0,0,0
endlayer

layer
0,0,0,0,0,0,0,0,0,0,0,0,0,0,0
0,0,0,0,0,0,0,0,0,0,0,0,0,0,0
0,0,0,0,0,0,0,0,0,0,0,0,0,0,0
0,0,0,0,0,4,0,0,0,4,0,0,0,0,0
0,0,0,0,0,0,0,0,0,0,0,0,0,0,0
0,0,0,4,0,0,0,0,0,0,0,4,0,0,0
0,0,0,0,0,0,0,0,0,0,0,0,0,0,0
0,0,0,0,0,0,0,0,0,0,0,0,0,0,0
0,0,0,0,0,0,0,0,0,0,0,0,0,0,0
0,0,0,4,0,0,0,0,0,0,0,4,0,0,0
0,0,0,0,0,0,0,0,0,0,0,0,0,0,0
0,0,0,0,0,4,0,0,0,4,0,0,0,0,0
0,0,0,0,0,0,0,0,0,0,0,0,0,0,0
0,0,0,0,0,0,0,0,0,0,0,0,0,0,0
0,0,0,0,0,0,0,0,0,0,0,0,0,0,0
endlayer

layer
0,0,0,0,0,0,0,0,0,0,0,0,0,0,0
0,0,0,0,0,0,0,0,0,0,0,0,0,0,0
0,0,0,0,0,0,0,0,0,0,0,0,0,0,0
0,0,0,0,0,4,0,0,0,4,0,0,0,0,0
0,0,0,0,0,0,0,0,0,0,0,0,0,0,0
0,0,0,4,0,0,0,0,0,0,0,4,0,0,0
0,0,0,0,0,0,0,0,0,0,0,0,0,0,0
0,0,0,0,0,0,0,0,0,0,0,0,0,0,0
0,0,0,0,0,0,0,0,0,0,0,0,0,0,0
0,0,0,4,0,0,0,0,0,0,0,4,0,0,0
0,0,0,0,0,0,0,0,0,0,0,0,0,0,0
0,0,0,0,0,4,0,0,0,4,0,0,0,0,0
0,0,0,0,0,0,0,0,0,0,0,0,0,0,0
0,0,0,0,0,0,0,0,0,0,0,0,0,0,0
0,0,0,0,0,0,0,0,0,0,0,0,0,0,0
endlayer

