{
    "registryname": "oil_empowerer",
    "localizedname": "Oil Empowerer",
    "color": "CC4747",
    "modifiers": [
                {
            "elements": "contenttweaker:speed_gearbox",
            "x": 0,
            "y": 1,
            "z": 0,
            "description": "Speed Gear! 50% Speed increase! Also increases energy requirement by 60%.",
            "modifier": {
                "io": "output",
                "target": "duration",
                "operation": 1,
                "multiplier": 0.66
            },
            
                "io": "input",
                "target": "energy",
                "operation": 1,
                "multiplier": 1.6
            },

            {
            "elements": "contenttweaker:power_gearbox",
            "x": 0,
            "y": 1,
            "z": 0,
            "description": "Power Gear! Uses 60% of normal power requirement! Also increases process time by 10%.",
            "modifier": {
                "io": "output",
                "target": "duration",
                "operation": 1,
                "multiplier": 1.10
            },
            
                "io": "input",
                "target": "energy",
                "operation": 1,
                "multiplier": 0.6
            },

            {
            "elements": "contenttweaker:double_gearbox",
            "x": 0,
            "y": 1,
            "z": 0,
            "description": "Double Gear! 30% less power used, 30% less processing time.",
            "modifier": {
                "io": "output",
                "target": "duration",
                "operation": 1,
                "multiplier": 0.7
            },
            
                "io": "input",
                "target": "energy",
                "operation": 1,
                "multiplier": 0.7
            },

                        {
            "elements": "contenttweaker:singular_torsion_speed_gearbox",
            "x": 0,
            "y": 1,
            "z": 0,
            "description": "Speed Gear! 200% Speed increase! Also increases energy requirement by 100%.",
            "modifier": {
                "io": "output",
                "target": "duration",
                "operation": 1,
                "multiplier": 0.33
            },
            
                "io": "input",
                "target": "energy",
                "operation": 1,
                "multiplier": 2.0
            },

            {
            "elements": "contenttweaker:singular_torsion_power_gearbox",
            "x": 0,
            "y": 1,
            "z": 0,
            "description": "Power Gear! Uses 40% of normal power requirement! Also increases process time by 15%.",
            "modifier": {
                "io": "output",
                "target": "duration",
                "operation": 1,
                "multiplier": 1.15
            },
            
                "io": "input",
                "target": "energy",
                "operation": 1,
                "multiplier": 0.4
            },

            {
            "elements": "contenttweaker:singular_torsion_double_gearbox",
            "x": 0,
            "y": 1,
            "z": 0,
            "description": "Double Gear! 45% less power used, 50% less processing time.",
            "modifier": {
                "io": "output",
                "target": "duration",
                "operation": 1,
                "multiplier": 0.5
            },
            
                "io": "input",
                "target": "energy",
                "operation": 1,
                "multiplier": 0.55
            },

            {
            "elements": "contenttweaker:quantum_synchronized_double_gearbox",
            "x": 0,
            "y": 1,
            "z": 0,
            "description": "Double Gear! 60% less power used, 75% less processing time.",
            "modifier": {
                "io": "output",
                "target": "duration",
                "operation": 1,
                "multiplier": 0.25
            },
            
                "io": "input",
                "target": "energy",
                "operation": 1,
                "multiplier": 0.4
            }

    ],
    "parts": [
        {
            "x": -2,
            "y": 0,
            "z": 2,
            "elements": [
                "modularmachinery:blockfluidoutputhatch"
            ]
        },
        {
            "x": -1,
            "y": 0,
            "z": 2,
            "elements": [
                "contenttweaker:blockcasing_empoweredredsteel@0"
            ]
        },
        {
            "x": 0,
            "y": 0,
            "z": 2,
            "elements": [
                "contenttweaker:blockcasing_empoweredredsteel@0"
            ]
        },
        {
            "x": 1,
            "y": 0,
            "z": 2,
            "elements": [
                "contenttweaker:blockcasing_empoweredredsteel@0"
            ]
        },
        {
            "x": 2,
            "y": 0,
            "z": 2,
            "elements": [
                "modularmachinery:blockfluidinputhatch"
            ]
        },
        {
            "x": 0,
            "y": 0,
            "z": 4,
            "elements": [
                "modularmachinery:blockinputbus"
            ]
        },
        {
            "x": 1,
            "y": -1,
            "z": 0,
            "elements": [
                "contenttweaker:blockcasing_duskstone@0"
            ]
        },
        {
            "x": 0,
            "y": -1,
            "z": 0,
            "elements": [
                "contenttweaker:blockcasing_steel@0"
            ]
        },
        {
            "x": -1,
            "y": 1,
            "z": 0,
            "elements": [
                "contenttweaker:blockcasing_duskstone@0"
            ]
        },
        {
            "x": 0,
            "y": 1,
            "z": 0,
            "elements": [
                "contenttweaker:blockcasing_steel@0"
            ]
        },
        {
            "x": -1,
            "y": -1,
            "z": 0,
            "elements": [
                "contenttweaker:blockcasing_duskstone@0"
            ]
        },
        {
            "x": -2,
            "y": 1,
            "z": 2,
            "elements": [
                "contenttweaker:blockcasing_steel@0"
            ]
        },
        {
            "x": -2,
            "y": -1,
            "z": 1,
            "elements": [
                "contenttweaker:blockcasing_duskstone@0"
            ]
        },
        {
            "x": -1,
            "y": 1,
            "z": 2,
            "elements": [
                "ic2:glass@0"
            ]
        },
        {
            "x": 1,
            "y": 1,
            "z": 0,
            "elements": [
                "contenttweaker:blockcasing_duskstone@0"
            ]
        },
        {
            "x": 0,
            "y": 1,
            "z": 2,
            "elements": [
                "modularmachinery:blockenergyinputhatch"
            ]
        },
        {
            "x": -1,
            "y": -1,
            "z": 1,
            "elements": [
                "contenttweaker:blockcasing_duskstone@0"
            ]
        },
        {
            "x": 0,
            "y": -1,
            "z": 1,
            "elements": [
                "ic2:glass@0"
            ]
        },
        {
            "x": -2,
            "y": -1,
            "z": 3,
            "elements": [
                "contenttweaker:blockcasing_duskstone@0"
            ]
        },
        {
            "x": -1,
            "y": 1,
            "z": 4,
            "elements": [
                "contenttweaker:blockcasing_duskstone@0"
            ]
        },
        {
            "x": 1,
            "y": 1,
            "z": 2,
            "elements": [
                "ic2:glass@0"
            ]
        },
        {
            "x": 0,
            "y": 1,
            "z": 4,
            "elements": [
                "contenttweaker:blockcasing_steel@0"
            ]
        },
        {
            "x": 2,
            "y": 1,
            "z": 2,
            "elements": [
                "contenttweaker:blockcasing_steel@0"
            ]
        },
        {
            "x": 1,
            "y": -1,
            "z": 1,
            "elements": [
                "contenttweaker:blockcasing_duskstone@0"
            ]
        },
        {
            "x": -1,
            "y": -1,
            "z": 3,
            "elements": [
                "contenttweaker:blockcasing_duskstone@0"
            ]
        },
        {
            "x": 0,
            "y": -1,
            "z": 3,
            "elements": [
                "ic2:glass@0"
            ]
        },
        {
            "x": 1,
            "y": 1,
            "z": 4,
            "elements": [
                "contenttweaker:blockcasing_duskstone@0"
            ]
        },
        {
            "x": 2,
            "y": -1,
            "z": 1,
            "elements": [
                "contenttweaker:blockcasing_duskstone@0"
            ]
        },
        {
            "x": 1,
            "y": -1,
            "z": 3,
            "elements": [
                "contenttweaker:blockcasing_duskstone@0"
            ]
        },
        {
            "x": 2,
            "y": -1,
            "z": 3,
            "elements": [
                "contenttweaker:blockcasing_duskstone@0"
            ]
        },
        {
            "x": -1,
            "y": 0,
            "z": 1,
            "elements": [
                "ic2:glass@0"
            ]
        },
        {
            "x": 0,
            "y": 0,
            "z": 1,
            "elements": [
                "contenttweaker:blockcasing_empoweredredsteel@0"
            ]
        },
        {
            "x": 1,
            "y": 0,
            "z": 1,
            "elements": [
                "ic2:glass@0"
            ]
        },
        {
            "x": -1,
            "y": 0,
            "z": 3,
            "elements": [
                "ic2:glass@0"
            ]
        },
        {
            "x": 0,
            "y": 0,
            "z": 3,
            "elements": [
                "contenttweaker:blockcasing_empoweredredsteel@0"
            ]
        },
        {
            "x": 1,
            "y": 0,
            "z": 3,
            "elements": [
                "ic2:glass@0"
            ]
        },
        {
            "x": -2,
            "y": 1,
            "z": 1,
            "elements": [
                "contenttweaker:blockcasing_duskstone@0"
            ]
        },
        {
            "x": -1,
            "y": 1,
            "z": 1,
            "elements": [
                "contenttweaker:blockcasing_duskstone@0"
            ]
        },
        {
            "x": 0,
            "y": 1,
            "z": 1,
            "elements": [
                "ic2:glass@0"
            ]
        },
        {
            "x": -2,
            "y": 1,
            "z": 3,
            "elements": [
                "contenttweaker:blockcasing_duskstone@0"
            ]
        },
        {
            "x": -2,
            "y": -1,
            "z": 2,
            "elements": [
                "contenttweaker:blockcasing_steel@0"
            ]
        },
        {
            "x": -1,
            "y": 1,
            "z": 3,
            "elements": [
                "contenttweaker:blockcasing_duskstone@0"
            ]
        },
        {
            "x": 1,
            "y": 1,
            "z": 1,
            "elements": [
                "contenttweaker:blockcasing_duskstone@0"
            ]
        },
        {
            "x": 0,
            "y": 1,
            "z": 3,
            "elements": [
                "ic2:glass@0"
            ]
        },
        {
            "x": 2,
            "y": 1,
            "z": 1,
            "elements": [
                "contenttweaker:blockcasing_duskstone@0"
            ]
        },
        {
            "x": -1,
            "y": -1,
            "z": 2,
            "elements": [
                "ic2:glass@0"
            ]
        },
        {
            "x": 0,
            "y": -1,
            "z": 2,
            "elements": [
                "contenttweaker:blockcasing_steel@0"
            ]
        },
        {
            "x": 1,
            "y": 1,
            "z": 3,
            "elements": [
                "contenttweaker:blockcasing_duskstone@0"
            ]
        },
        {
            "x": 2,
            "y": 1,
            "z": 3,
            "elements": [
                "contenttweaker:blockcasing_duskstone@0"
            ]
        },
        {
            "x": 1,
            "y": -1,
            "z": 2,
            "elements": [
                "ic2:glass@0"
            ]
        },
        {
            "x": -1,
            "y": -1,
            "z": 4,
            "elements": [
                "contenttweaker:blockcasing_duskstone@0"
            ]
        },
        {
            "x": 0,
            "y": -1,
            "z": 4,
            "elements": [
                "contenttweaker:blockcasing_steel@0"
            ]
        },
        {
            "x": 2,
            "y": -1,
            "z": 2,
            "elements": [
                "contenttweaker:blockcasing_steel@0"
            ]
        },
        {
            "x": 1,
            "y": -1,
            "z": 4,
            "elements": [
                "contenttweaker:blockcasing_duskstone@0"
            ]
        }
    ]}